<?xml version="1.0" ?>
<!-- =================================================================================== -->
<!-- |    This document was autogenerated by xacro from manipulator.urdf.xacro         | -->
<!-- |    EDITING THIS FILE BY HAND IS NOT RECOMMENDED                                 | -->
<!-- =================================================================================== -->
<robot name="ur_manipulator">
  <!-- "example ur3" -->
  <!-- ########################################################################################################################### -->
  <!-- ########################################################################################################################### -->
  <!-- Global world frame -->
  <link name="world"/>
  <!-- Fix the base to the given parent -->
  <joint name="ur3_attachment_to_world" type="fixed">
    <parent link="world"/>
    <child link="ur3_attachment_base_link"/>
    <origin rpy="0 0 0" xyz="0 0 0"/>
  </joint>
  <!-- Cylinder base -->
  <link name="ur3_attachment_base_link">
    <visual>
      <geometry>
        <cylinder length="0.85" radius="0.1"/>
      </geometry>
      <material name="grey">
        <color rgba="0.5 0.5 0.5 1.0"/>
      </material>
      <origin rpy="0 0 0" xyz="0 0 0"/>
    </visual>
    <collision>
      <geometry>
        <cylinder length="0.85" radius="0.1"/>
      </geometry>
      <origin rpy="0 0 0" xyz="0 0 0"/>
    </collision>
    <inertial>
      <mass value="10.0"/>
      <origin rpy="0 0 0" xyz="0 0 0"/>
      <inertia ixx="0.1" ixy="0.0" ixz="0.0" iyy="0.1" iyz="0.0" izz="0.1"/>
    </inertial>
  </link>
  <!-- Mount link ABOVE the cylinder (no <origin> inside link!) -->
  <link name="ur3_attachment_mount_link"/>
  <!-- Fixed transform: base_link -> mount_link at the top face -->
  <joint name="ur3_attachment_base_to_mount" type="fixed">
    <parent link="ur3_attachment_base_link"/>
    <child link="ur3_attachment_mount_link"/>
    <!-- If height=0.85, top is +0.425 from center -->
    <origin rpy="0 0 0" xyz="0 0 0.425"/>
  </joint>
  <!--
    Base UR robot series xacro macro.

    NOTE this is NOT a URDF. It cannot directly be loaded by consumers
    expecting a flattened '.urdf' file. See the top-level '.xacro' for that
    (but note that .xacro must still be processed by the xacro command).

    This file models the base kinematic chain of a UR robot, which then gets
    parameterised by various configuration files to convert it into a UR3(e),
    UR5(e), UR10(e) or UR16e.

    NOTE the default kinematic parameters (i.e., link lengths, frame locations,
    offsets, etc) do not correspond to any particular robot. They are defaults
    only. There WILL be non-zero offsets between the Forward Kinematics results
    in TF (i.e., robot_state_publisher) and the values reported by the Teach
    Pendant.

    For accurate (and robot-specific) transforms, the 'kinematics_parameters_file'
    parameter MUST point to a .yaml file containing the appropriate values for
    the targeted robot.

    If using the UniversalRobots/Universal_Robots_ROS_Driver, follow the steps
    described in the readme of that repository to extract the kinematic
    calibration from the controller and generate the required .yaml file.

    Main author of the migration to yaml configs Ludovic Delval.

    Contributors to previous versions (in no particular order)

     - Denis Stogl
     - Lovro Ivanov
     - Felix Messmer
     - Kelsey Hawkins
     - Wim Meeussen
     - Shaun Edwards
     - Nadia Hammoudeh Garcia
     - Dave Hershberger
     - G. vd. Hoorn
     - Philip Long
     - Dave Coleman
     - Miguel Prada
     - Mathias Luedtke
     - Marcel Schnirring
     - Felix von Drigalski
     - Felix Exner
     - Jimmy Da Silva
     - Ajit Krisshna N L
     - Muhammad Asif Rana
  -->
  <!-- links -  main serial chain -->
  <!-- base_link serves as the root of the robot's kinematic tree. It follows REP-103
        conventions (i.e., X+ forward, Y+ left, Z+ up).
        Since some kinematic solvers forbid having inertia values attached to a root link, we've
        added the base_link_inertia link that carries the visual, collision and inertia
        information.
    -->
  <link name="ur3_base_link"/>
  <link name="ur3_base_link_inertia">
    <visual>
      <origin rpy="0.0 0.0 3.141592653589793" xyz="0.0 0.0 0.0"/>
      <geometry>
        <mesh filename="package://ur_description/meshes/ur3/visual/base.dae"/>
      </geometry>
    </visual>
    <collision>
      <origin rpy="0.0 0.0 3.141592653589793" xyz="0.0 0.0 0.0"/>
      <geometry>
        <mesh filename="package://ur_description/meshes/ur3/collision/base.stl"/>
      </geometry>
    </collision>
    <inertial>
      <mass value="2.0"/>
      <origin rpy="0 0 0" xyz="0 0 0"/>
      <inertia ixx="0.0030531654454" ixy="0.0" ixz="0.0" iyy="0.0030531654454" iyz="0.0" izz="0.005625"/>
    </inertial>
  </link>
  <link name="ur3_shoulder_link">
    <visual>
      <origin rpy="0.0 0.0 3.141592653589793" xyz="0.0 0.0 0.0"/>
      <geometry>
        <mesh filename="package://ur_description/meshes/ur3/visual/shoulder.dae"/>
      </geometry>
    </visual>
    <collision>
      <origin rpy="0.0 0.0 3.141592653589793" xyz="0.0 0.0 0.0"/>
      <geometry>
        <mesh filename="package://ur_description/meshes/ur3/collision/shoulder.stl"/>
      </geometry>
    </collision>
    <inertial>
      <mass value="2.0"/>
      <origin rpy="0 0 0" xyz="0.0 0.0 -0.02"/>
      <inertia ixx="0.008093166666666665" ixy="0" ixz="0" iyy="0.008093166666666665" iyz="0" izz="0.005625"/>
    </inertial>
  </link>
  <link name="ur3_upper_arm_link">
    <visual>
      <origin rpy="1.5707963267948966 0.0 -1.5707963267948966" xyz="0.0 0.0 0.1198"/>
      <geometry>
        <mesh filename="package://ur_description/meshes/ur3/visual/upperarm.dae"/>
      </geometry>
    </visual>
    <collision>
      <origin rpy="1.5707963267948966 0.0 -1.5707963267948966" xyz="0.0 0.0 0.1198"/>
      <geometry>
        <mesh filename="package://ur_description/meshes/ur3/collision/upperarm.stl"/>
      </geometry>
    </collision>
    <inertial>
      <mass value="3.42"/>
      <origin rpy="0 1.570796326794897 0" xyz="-0.11365 0.0 0.1157"/>
      <inertia ixx="0.021728491912499998" ixy="0" ixz="0" iyy="0.021728491912499998" iyz="0" izz="0.00961875"/>
    </inertial>
  </link>
  <link name="ur3_forearm_link">
    <visual>
      <origin rpy="1.5707963267948966 0.0 -1.5707963267948966" xyz="0.0 0.0 0.0275"/>
      <geometry>
        <mesh filename="package://ur_description/meshes/ur3/visual/forearm.dae"/>
      </geometry>
    </visual>
    <collision>
      <origin rpy="1.5707963267948966 0.0 -1.5707963267948966" xyz="0.0 0.0 0.0275"/>
      <geometry>
        <mesh filename="package://ur_description/meshes/ur3/collision/forearm.stl"/>
      </geometry>
    </collision>
    <inertial>
      <mass value="1.26"/>
      <origin rpy="0 1.570796326794897 0" xyz="-0.16325 0.0 0.0238"/>
      <inertia ixx="0.0065468090625" ixy="0" ixz="0" iyy="0.0065468090625" iyz="0" izz="0.00354375"/>
    </inertial>
  </link>
  <link name="ur3_wrist_1_link">
    <visual>
      <origin rpy="1.5707963267948966 0.0 0.0" xyz="0.0 0.0 -0.085"/>
      <geometry>
        <mesh filename="package://ur_description/meshes/ur3/visual/wrist1.dae"/>
      </geometry>
    </visual>
    <collision>
      <origin rpy="1.5707963267948966 0.0 0.0" xyz="0.0 0.0 -0.085"/>
      <geometry>
        <mesh filename="package://ur_description/meshes/ur3/collision/wrist1.stl"/>
      </geometry>
    </collision>
    <inertial>
      <mass value="0.8"/>
      <origin rpy="0 0 0" xyz="0.0 -0.01 0.0"/>
      <inertia ixx="0.0016106414999999998" ixy="0" ixz="0" iyy="0.0016106414999999998" iyz="0" izz="0.00225"/>
    </inertial>
  </link>
  <link name="ur3_wrist_2_link">
    <visual>
      <origin rpy="0.0 0.0 0.0" xyz="0.0 0.0 -0.083"/>
      <geometry>
        <mesh filename="package://ur_description/meshes/ur3/visual/wrist2.dae"/>
      </geometry>
    </visual>
    <collision>
      <origin rpy="0.0 0.0 0.0" xyz="0.0 0.0 -0.083"/>
      <geometry>
        <mesh filename="package://ur_description/meshes/ur3/collision/wrist2.stl"/>
      </geometry>
    </collision>
    <inertial>
      <mass value="0.8"/>
      <origin rpy="0 0 0" xyz="0.0 0.01 0.0"/>
      <inertia ixx="0.0015721739999999998" ixy="0" ixz="0" iyy="0.0015721739999999998" iyz="0" izz="0.00225"/>
    </inertial>
  </link>
  <link name="ur3_wrist_3_link">
    <visual>
      <origin rpy="1.5707963267948966 0.0 0.0" xyz="0.0 -0.00255 -0.082"/>
      <geometry>
        <mesh filename="package://ur_description/meshes/ur3/visual/wrist3.dae"/>
      </geometry>
    </visual>
    <collision>
      <origin rpy="1.5707963267948966 0.0 0.0" xyz="0.0 -0.00255 -0.082"/>
      <geometry>
        <mesh filename="package://ur_description/meshes/ur3/collision/wrist3.stl"/>
      </geometry>
    </collision>
    <inertial>
      <mass value="0.35"/>
      <origin rpy="0 0 0" xyz="0.0 0.0 -0.02"/>
      <inertia ixx="0.00013626666666666665" ixy="0" ixz="0" iyy="0.00013626666666666665" iyz="0" izz="0.0001792"/>
    </inertial>
  </link>
  <!-- base_joint fixes base_link to the environment -->
  <joint name="ur3_base_joint" type="fixed">
    <origin rpy="0 0 0" xyz="0 0 0"/>
    <parent link="ur3_attachment_mount_link"/>
    <child link="ur3_base_link"/>
  </joint>
  <!-- joints - main serial chain -->
  <joint name="ur3_base_link-base_link_inertia" type="fixed">
    <parent link="ur3_base_link"/>
    <child link="ur3_base_link_inertia"/>
    <!-- 'base_link' is REP-103 aligned (so X+ forward), while the internal
           frames of the robot/controller have X+ pointing backwards.
           Use the joint between 'base_link' and 'base_link_inertia' (a dummy
           link/frame) to introduce the necessary rotation over Z (of pi rad).
      -->
    <origin rpy="0 0 3.141592653589793" xyz="0 0 0"/>
  </joint>
  <joint name="ur3_shoulder_pan_joint" type="revolute">
    <parent link="ur3_base_link_inertia"/>
    <child link="ur3_shoulder_link"/>
    <origin rpy="0 0 0" xyz="0 0 0.1519"/>
    <axis xyz="0 0 1"/>
    <limit effort="56.0" lower="-6.283185307179586" upper="6.283185307179586" velocity="3.141592653589793"/>
    <dynamics damping="0" friction="0"/>
  </joint>
  <joint name="ur3_shoulder_lift_joint" type="revolute">
    <parent link="ur3_shoulder_link"/>
    <child link="ur3_upper_arm_link"/>
    <origin rpy="1.570796327 0 0" xyz="0 0 0"/>
    <axis xyz="0 0 1"/>
    <limit effort="56.0" lower="-6.283185307179586" upper="6.283185307179586" velocity="3.141592653589793"/>
    <dynamics damping="0" friction="0"/>
  </joint>
  <joint name="ur3_elbow_joint" type="revolute">
    <parent link="ur3_upper_arm_link"/>
    <child link="ur3_forearm_link"/>
    <origin rpy="0 0 0" xyz="-0.24365 0 0"/>
    <axis xyz="0 0 1"/>
    <limit effort="28.0" lower="-3.141592653589793" upper="3.141592653589793" velocity="3.141592653589793"/>
    <dynamics damping="0" friction="0"/>
  </joint>
  <joint name="ur3_wrist_1_joint" type="revolute">
    <parent link="ur3_forearm_link"/>
    <child link="ur3_wrist_1_link"/>
    <origin rpy="0 0 0" xyz="-0.21325 0 0.11235"/>
    <axis xyz="0 0 1"/>
    <limit effort="12.0" lower="-6.283185307179586" upper="6.283185307179586" velocity="6.283185307179586"/>
    <dynamics damping="0" friction="0"/>
  </joint>
  <joint name="ur3_wrist_2_joint" type="revolute">
    <parent link="ur3_wrist_1_link"/>
    <child link="ur3_wrist_2_link"/>
    <origin rpy="1.570796327 0 0" xyz="0 -0.08535 -1.750557762378351e-11"/>
    <axis xyz="0 0 1"/>
    <limit effort="12.0" lower="-6.283185307179586" upper="6.283185307179586" velocity="6.283185307179586"/>
    <dynamics damping="0" friction="0"/>
  </joint>
  <joint name="ur3_wrist_3_joint" type="continuous">
    <parent link="ur3_wrist_2_link"/>
    <child link="ur3_wrist_3_link"/>
    <origin rpy="1.570796326589793 3.141592653589793 3.141592653589793" xyz="0 0.0819 -1.679797079540562e-11"/>
    <axis xyz="0 0 1"/>
    <limit effort="12.0" velocity="6.283185307179586"/>
    <dynamics damping="0" friction="0"/>
  </joint>
  <link name="ur3_ft_frame"/>
  <joint name="ur3_wrist_3_link-ft_frame" type="fixed">
    <parent link="ur3_wrist_3_link"/>
    <child link="ur3_ft_frame"/>
    <origin rpy="3.141592653589793 0 0" xyz="0 0 0"/>
  </joint>
  <!-- ROS-Industrial 'base' frame - base_link to UR 'Base' Coordinates transform -->
  <link name="ur3_base"/>
  <joint name="ur3_base_link-base_fixed_joint" type="fixed">
    <!-- Note the rotation over Z of pi radians - as base_link is REP-103
           aligned (i.e., has X+ forward, Y+ left and Z+ up), this is needed
           to correctly align 'base' with the 'Base' coordinate system of
           the UR controller.
      -->
    <origin rpy="0 0 3.141592653589793" xyz="0 0 0"/>
    <parent link="ur3_base_link"/>
    <child link="ur3_base"/>
  </joint>
  <!-- ROS-Industrial 'flange' frame - attachment point for EEF models -->
  <link name="ur3_flange"/>
  <joint name="ur3_wrist_3-flange" type="fixed">
    <parent link="ur3_wrist_3_link"/>
    <child link="ur3_flange"/>
    <origin rpy="0 -1.5707963267948966 -1.5707963267948966" xyz="0 0 0"/>
  </joint>
  <!-- ROS-Industrial 'tool0' frame - all-zeros tool frame -->
  <link name="ur3_tool0"/>
  <joint name="ur3_flange-tool0" type="fixed">
    <!-- default toolframe - X+ left, Y+ up, Z+ front -->
    <origin rpy="1.5707963267948966 0 1.5707963267948966" xyz="0 0 0"/>
    <parent link="ur3_flange"/>
    <child link="ur3_tool0"/>
  </joint>
  <ros2_control name="ur3" type="system">
    <hardware>
      <plugin>mock_components/GenericSystem</plugin>
      <param name="mock_sensor_commands">False</param>
      <param name="state_following_offset">0.0</param>
      <param name="calculate_dynamics">true</param>
    </hardware>
    <joint name="ur3_shoulder_pan_joint">
      <command_interface name="position"/>
      <command_interface name="velocity"/>
      <state_interface name="position">
        <!-- initial position for the mock system and simulation -->
        <param name="initial_value">0.0</param>
      </state_interface>
      <state_interface name="velocity">
        <param name="initial_value">0.0</param>
      </state_interface>
      <state_interface name="effort">
        <param name="initial_value">0.0</param>
      </state_interface>
    </joint>
    <joint name="ur3_shoulder_lift_joint">
      <command_interface name="position"/>
      <command_interface name="velocity"/>
      <state_interface name="position">
        <!-- initial position for the mock system and simulation -->
        <param name="initial_value">-1.57</param>
      </state_interface>
      <state_interface name="velocity">
        <param name="initial_value">0.0</param>
      </state_interface>
      <state_interface name="effort">
        <param name="initial_value">0.0</param>
      </state_interface>
    </joint>
    <joint name="ur3_elbow_joint">
      <command_interface name="position"/>
      <command_interface name="velocity"/>
      <state_interface name="position">
        <!-- initial position for the mock system and simulation -->
        <param name="initial_value">0.0</param>
      </state_interface>
      <state_interface name="velocity">
        <param name="initial_value">0.0</param>
      </state_interface>
      <state_interface name="effort">
        <param name="initial_value">0.0</param>
      </state_interface>
    </joint>
    <joint name="ur3_wrist_1_joint">
      <command_interface name="position"/>
      <command_interface name="velocity"/>
      <state_interface name="position">
        <!-- initial position for the mock system and simulation -->
        <param name="initial_value">-1.57</param>
      </state_interface>
      <state_interface name="velocity">
        <param name="initial_value">0.0</param>
      </state_interface>
      <state_interface name="effort">
        <param name="initial_value">0.0</param>
      </state_interface>
    </joint>
    <joint name="ur3_wrist_2_joint">
      <command_interface name="position"/>
      <command_interface name="velocity"/>
      <state_interface name="position">
        <!-- initial position for the mock system and simulation -->
        <param name="initial_value">0.0</param>
      </state_interface>
      <state_interface name="velocity">
        <param name="initial_value">0.0</param>
      </state_interface>
      <state_interface name="effort">
        <param name="initial_value">0.0</param>
      </state_interface>
    </joint>
    <joint name="ur3_wrist_3_joint">
      <command_interface name="position"/>
      <command_interface name="velocity"/>
      <state_interface name="position">
        <!-- initial position for the mock system and simulation -->
        <param name="initial_value">0.0</param>
      </state_interface>
      <state_interface name="velocity">
        <param name="initial_value">0.0</param>
      </state_interface>
      <state_interface name="effort">
        <param name="initial_value">0.0</param>
      </state_interface>
    </joint>
    <sensor name="ur3_tcp_fts_sensor">
      <state_interface name="force.x"/>
      <state_interface name="force.y"/>
      <state_interface name="force.z"/>
      <state_interface name="torque.x"/>
      <state_interface name="torque.y"/>
      <state_interface name="torque.z"/>
    </sensor>
    <sensor name="ur3_tcp_pose">
      <state_interface name="position.x"/>
      <state_interface name="position.y"/>
      <state_interface name="position.z"/>
      <state_interface name="orientation.x"/>
      <state_interface name="orientation.y"/>
      <state_interface name="orientation.z"/>
      <state_interface name="orientation.w"/>
    </sensor>
  </ros2_control>
</robot>
